  File "/opt/render/project/src/.venv/lib/python3.13/site-packages/sqlalchemy/pool/base.py", line 899, in __connect
    with util.safe_reraise():
         ~~~~~~~~~~~~~~~~~^^
  File "/opt/render/project/src/.venv/lib/python3.13/site-packages/sqlalchemy/util/langhelpers.py", line 224, in __exit__
    raise exc_value.with_traceback(exc_tb)
  File "/opt/render/project/src/.venv/lib/python3.13/site-packages/sqlalchemy/pool/base.py", line 895, in __connect
    self.dbapi_connection = connection = pool._invoke_creator(self)
                                         ~~~~~~~~~~~~~~~~~~~~^^^^^^
  File "/opt/render/project/src/.venv/lib/python3.13/site-packages/sqlalchemy/engine/create.py", line 661, in connect
    return dialect.connect(*cargs, **cparams)
           ~~~~~~~~~~~~~~~^^^^^^^^^^^^^^^^^^^
  File "/opt/render/project/src/.venv/lib/python3.13/site-packages/sqlalchemy/engine/default.py", line 629, in connect
    return self.loaded_dbapi.connect(*cargs, **cparams)  # type: ignore[no-any-return]  # NOQA: E501
           ~~~~~~~~~~~~~~~~~~~~~~~~~^^^^^^^^^^^^^^^^^^^
  File "/opt/render/project/src/.venv/lib/python3.13/site-packages/psycopg2/__init__.py", line 122, in connect
    conn = _connect(dsn, connection_factory=connection_factory, **kwasync)
sqlalchemy.exc.OperationalError: (psycopg2.OperationalError) could not translate host name "dpg-d2sq2275r7bs73aocip0-a" to address: Name or service not known
(Background on this error at: https://sqlalche.me/e/20/e3q8)
==> Exited with status 1
==> Common ways to troubleshoot your deploy: https://render.com/docs/troubleshooting-deploys
==> Running 'gunicorn main:app'
[03:10:19] INFO: Chatbot Factory AI logging system initialized successfully
[03:10:19] INFO: Chatbot Factory AI logging system initialized successfully
[03:10:19] INFO: Chatbot Factory AI application starting with professional logging
[03:10:19] INFO: Using PostgreSQL with production-optimized connection pooling (Render.com)
[03:10:44] INFO: Production environment detected - using optimized database settings
[03:10:44] ERROR: PRODUCTION DATABASE ERROR: (psycopg2.OperationalError) could not translate host name "dpg-d2sq2275r7bs73aocip0-a" to address: Name or service not known
(Background on this error at: https://sqlalche.me/e/20/e3q8)
[03:10:44] ERROR: Check Render.com dashboard: Database service, Environment variables, Logs
Traceback (most recent call last):
  File "/opt/render/project/src/.venv/lib/python3.13/site-packages/sqlalchemy/engine/base.py", line 143, in __init__
    self._dbapi_connection = engine.raw_connection()
                             ~~~~~~~~~~~~~~~~~~~~~^^
  File "/opt/render/project/src/.venv/lib/python3.13/site-packages/sqlalchemy/engine/base.py", line 3301, in raw_connection
    return self.pool.connect()
           ~~~~~~~~~~~~~~~~~^^
  File "/opt/render/project/src/.venv/lib/python3.13/site-packages/sqlalchemy/pool/base.py", line 447, in connect
    return _ConnectionFairy._checkout(self)
           ~~~~~~~~~~~~~~~~~~~~~~~~~~^^^^^^
  File "/opt/render/project/src/.venv/lib/python3.13/site-packages/sqlalchemy/pool/base.py", line 1264, in _checkout
    fairy = _ConnectionRecord.checkout(pool)
  File "/opt/render/project/src/.venv/lib/python3.13/site-packages/sqlalchemy/pool/base.py", line 711, in checkout
    rec = pool._do_get()
  File "/opt/render/project/src/.venv/lib/python3.13/site-packages/sqlalchemy/pool/impl.py", line 177, in _do_get
    with util.safe_reraise():
         ~~~~~~~~~~~~~~~~~^^
  File "/opt/render/project/src/.venv/lib/python3.13/site-packages/sqlalchemy/util/langhelpers.py", line 224, in __exit__
    raise exc_value.with_traceback(exc_tb)
  File "/opt/render/project/src/.venv/lib/python3.13/site-packages/sqlalchemy/pool/impl.py", line 175, in _do_get
    return self._create_connection()
           ~~~~~~~~~~~~~~~~~~~~~~~^^
  File "/opt/render/project/src/.venv/lib/python3.13/site-packages/sqlalchemy/pool/base.py", line 388, in _create_connection
    return _ConnectionRecord(self)
  File "/opt/render/project/src/.venv/lib/python3.13/site-packages/sqlalchemy/pool/base.py", line 673, in __init__
    self.__connect()
    ~~~~~~~~~~~~~~^^
  File "/opt/render/project/src/.venv/lib/python3.13/site-packages/sqlalchemy/pool/base.py", line 899, in __connect
    with util.safe_reraise():
         ~~~~~~~~~~~~~~~~~^^
  File "/opt/render/project/src/.venv/lib/python3.13/site-packages/sqlalchemy/util/langhelpers.py", line 224, in __exit__
    raise exc_value.with_traceback(exc_tb)
  File "/opt/render/project/src/.venv/lib/python3.13/site-packages/sqlalchemy/pool/base.py", line 895, in __connect
    self.dbapi_connection = connection = pool._invoke_creator(self)
                                         ~~~~~~~~~~~~~~~~~~~~^^^^^^
  File "/opt/render/project/src/.venv/lib/python3.13/site-packages/sqlalchemy/engine/create.py", line 661, in connect
    return dialect.connect(*cargs, **cparams)
           ~~~~~~~~~~~~~~~^^^^^^^^^^^^^^^^^^^
  File "/opt/render/project/src/.venv/lib/python3.13/site-packages/sqlalchemy/engine/default.py", line 629, in connect
    return self.loaded_dbapi.connect(*cargs, **cparams)  # type: ignore[no-any-return]  # NOQA: E501
           ~~~~~~~~~~~~~~~~~~~~~~~~~^^^^^^^^^^^^^^^^^^^
  File "/opt/render/project/src/.venv/lib/python3.13/site-packages/psycopg2/__init__.py", line 122, in connect
    conn = _connect(dsn, connection_factory=connection_factory, **kwasync)
psycopg2.OperationalError: could not translate host name "dpg-d2sq2275r7bs73aocip0-a" to address: Name or service not known
The above exception was the direct cause of the following exception:
Traceback (most recent call last):
  File "/opt/render/project/src/.venv/bin/gunicorn", line 8, in <module>
    sys.exit(run())
             ~~~^^
  File "/opt/render/project/src/.venv/lib/python3.13/site-packages/gunicorn/app/wsgiapp.py", line 66, in run
    WSGIApplication("%(prog)s [OPTIONS] [APP_MODULE]", prog=prog).run()
    ~~~~~~~~~~~~~~~~~~~~~~~~~~~~~~~~~~~~~~~~~~~~~~~~~~~~~~~~~~~~~~~~~^^
  File "/opt/render/project/src/.venv/lib/python3.13/site-packages/gunicorn/app/base.py", line 235, in run
    super().run()
    ~~~~~~~~~~~^^
  File "/opt/render/project/src/.venv/lib/python3.13/site-packages/gunicorn/app/base.py", line 71, in run
    Arbiter(self).run()
    ~~~~~~~^^^^^^
  File "/opt/render/project/src/.venv/lib/python3.13/site-packages/gunicorn/arbiter.py", line 57, in __init__
    self.setup(app)
    ~~~~~~~~~~^^^^^
  File "/opt/render/project/src/.venv/lib/python3.13/site-packages/gunicorn/arbiter.py", line 117, in setup
    self.app.wsgi()
    ~~~~~~~~~~~~~^^
  File "/opt/render/project/src/.venv/lib/python3.13/site-packages/gunicorn/app/base.py", line 66, in wsgi
    self.callable = self.load()
                    ~~~~~~~~~^^
  File "/opt/render/project/src/.venv/lib/python3.13/site-packages/gunicorn/app/wsgiapp.py", line 57, in load
    return self.load_wsgiapp()
           ~~~~~~~~~~~~~~~~~^^
  File "/opt/render/project/src/.venv/lib/python3.13/site-packages/gunicorn/app/wsgiapp.py", line 47, in load_wsgiapp
    return util.import_app(self.app_uri)
           ~~~~~~~~~~~~~~~^^^^^^^^^^^^^^
  File "/opt/render/project/src/.venv/lib/python3.13/site-packages/gunicorn/util.py", line 370, in import_app
    mod = importlib.import_module(module)
  File "/opt/render/project/python/Python-3.13.4/lib/python3.13/importlib/__init__.py", line 88, in import_module
    return _bootstrap._gcd_import(name[level:], package, level)
           ~~~~~~~~~~~~~~~~~~~~~~^^^^^^^^^^^^^^^^^^^^^^^^^^^^^^
  File "<frozen importlib._bootstrap>", line 1387, in _gcd_import
  File "<frozen importlib._bootstrap>", line 1360, in _find_and_load
  File "<frozen importlib._bootstrap>", line 1331, in _find_and_load_unlocked
  File "<frozen importlib._bootstrap>", line 935, in _load_unlocked
  File "<frozen importlib._bootstrap_external>", line 1026, in exec_module
  File "<frozen importlib._bootstrap>", line 488, in _call_with_frames_removed
  File "/opt/render/project/src/main.py", line 1, in <module>
    from app import app
  File "/opt/render/project/src/app.py", line 171, in <module>
    db.create_all()
    ~~~~~~~~~~~~~^^
  File "/opt/render/project/src/.venv/lib/python3.13/site-packages/flask_sqlalchemy/extension.py", line 900, in create_all
    self._call_for_binds(bind_key, "create_all")
    ~~~~~~~~~~~~~~~~~~~~^^^^^^^^^^^^^^^^^^^^^^^^
  File "/opt/render/project/src/.venv/lib/python3.13/site-packages/flask_sqlalchemy/extension.py", line 881, in _call_for_binds
    getattr(metadata, op_name)(bind=engine)
    ~~~~~~~~~~~~~~~~~~~~~~~~~~^^^^^^^^^^^^^
  File "/opt/render/project/src/.venv/lib/python3.13/site-packages/sqlalchemy/sql/schema.py", line 5924, in create_all
    bind._run_ddl_visitor(
    ~~~~~~~~~~~~~~~~~~~~~^
        ddl.SchemaGenerator, self, checkfirst=checkfirst, tables=tables
        ^^^^^^^^^^^^^^^^^^^^^^^^^^^^^^^^^^^^^^^^^^^^^^^^^^^^^^^^^^^^^^^
    )
    ^
  File "/opt/render/project/src/.venv/lib/python3.13/site-packages/sqlalchemy/engine/base.py", line 3251, in _run_ddl_visitor
    with self.begin() as conn:
         ~~~~~~~~~~^^
  File "/opt/render/project/python/Python-3.13.4/lib/python3.13/contextlib.py", line 141, in __enter__
    return next(self.gen)
  File "/opt/render/project/src/.venv/lib/python3.13/site-packages/sqlalchemy/engine/base.py", line 3241, in begin
    with self.connect() as conn:
         ~~~~~~~~~~~~^^
  File "/opt/render/project/src/.venv/lib/python3.13/site-packages/sqlalchemy/engine/base.py", line 3277, in connect
    return self._connection_cls(self)
           ~~~~~~~~~~~~~~~~~~~~^^^^^^
  File "/opt/render/project/src/.venv/lib/python3.13/site-packages/sqlalchemy/engine/base.py", line 145, in __init__
    Connection._handle_dbapi_exception_noconnection(
    ~~~~~~~~~~~~~~~~~~~~~~~~~~~~~~~~~~~~~~~~~~~~~~~^
        err, dialect, engine
        ^^^^^^^^^^^^^^^^^^^^
    )
    ^
  File "/opt/render/project/src/.venv/lib/python3.13/site-packages/sqlalchemy/engine/base.py", line 2440, in _handle_dbapi_exception_noconnection
    raise sqlalchemy_exception.with_traceback(exc_info[2]) from e
  File "/opt/render/project/src/.venv/lib/python3.13/site-packages/sqlalchemy/engine/base.py", line 143, in __init__
    self._dbapi_connection = engine.raw_connection()
                             ~~~~~~~~~~~~~~~~~~~~~^^
  File "/opt/render/project/src/.venv/lib/python3.13/site-packages/sqlalchemy/engine/base.py", line 3301, in raw_connection
    return self.pool.connect()
           ~~~~~~~~~~~~~~~~~^^
  File "/opt/render/project/src/.venv/lib/python3.13/site-packages/sqlalchemy/pool/base.py", line 447, in connect
    return _ConnectionFairy._checkout(self)
           ~~~~~~~~~~~~~~~~~~~~~~~~~~^^^^^^
  File "/opt/render/project/src/.venv/lib/python3.13/site-packages/sqlalchemy/pool/base.py", line 1264, in _checkout
    fairy = _ConnectionRecord.checkout(pool)
  File "/opt/render/project/src/.venv/lib/python3.13/site-packages/sqlalchemy/pool/base.py", line 711, in checkout
    rec = pool._do_get()
  File "/opt/render/project/src/.venv/lib/python3.13/site-packages/sqlalchemy/pool/impl.py", line 177, in _do_get
    with util.safe_reraise():
         ~~~~~~~~~~~~~~~~~^^
  File "/opt/render/project/src/.venv/lib/python3.13/site-packages/sqlalchemy/util/langhelpers.py", line 224, in __exit__
    raise exc_value.with_traceback(exc_tb)
  File "/opt/render/project/src/.venv/lib/python3.13/site-packages/sqlalchemy/pool/impl.py", line 175, in _do_get
    return self._create_connection()
           ~~~~~~~~~~~~~~~~~~~~~~~^^
  File "/opt/render/project/src/.venv/lib/python3.13/site-packages/sqlalchemy/pool/base.py", line 388, in _create_connection
    return _ConnectionRecord(self)
  File "/opt/render/project/src/.venv/lib/python3.13/site-packages/sqlalchemy/pool/base.py", line 673, in __init__
    self.__connect()
    ~~~~~~~~~~~~~~^^
  File "/opt/render/project/src/.venv/lib/python3.13/site-packages/sqlalchemy/pool/base.py", line 899, in __connect
    with util.safe_reraise():
         ~~~~~~~~~~~~~~~~~^^
  File "/opt/render/project/src/.venv/lib/python3.13/site-packages/sqlalchemy/util/langhelpers.py", line 224, in __exit__
    raise exc_value.with_traceback(exc_tb)
  File "/opt/render/project/src/.venv/lib/python3.13/site-packages/sqlalchemy/pool/base.py", line 895, in __connect
    self.dbapi_connection = connection = pool._invoke_creator(self)
                                         ~~~~~~~~~~~~~~~~~~~~^^^^^^
  File "/opt/render/project/src/.venv/lib/python3.13/site-packages/sqlalchemy/engine/create.py", line 661, in connect
    return dialect.connect(*cargs, **cparams)
           ~~~~~~~~~~~~~~~^^^^^^^^^^^^^^^^^^^
  File "/opt/render/project/src/.venv/lib/python3.13/site-packages/sqlalchemy/engine/default.py", line 629, in connect
    return self.loaded_dbapi.connect(*cargs, **cparams)  # type: ignore[no-any-return]  # NOQA: E501
           ~~~~~~~~~~~~~~~~~~~~~~~~~^^^^^^^^^^^^^^^^^^^
  File "/opt/render/project/src/.venv/lib/python3.13/site-packages/psycopg2/__init__.py", line 122, in connect
    conn = _connect(dsn, connection_factory=connection_factory, **kwasync)
sqlalchemy.exc.OperationalError: (psycopg2.OperationalError) could not translate host name "dpg-d2sq2275r7bs73aocip0-a" to address: Name or service not known
(Background on this error at: https://sqlalche.me/e/20/e3q8)