Using cached wtforms-3.2.1-py3-none-any.whl (152 kB)
Installing collected packages: telegram, pytz, pydub, websockets, urllib3, uritemplate, tzlocal, tzdata, typing-extensions, types-PyYAML, types-pytz, types-protobuf, tqdm, tornado, tenacity, socksio, sniffio, six, schedule, PyYAML, pyparsing, pycparser, pyasn1, psycopg2-binary, protobuf, Pillow, packaging, numpy, markupsafe, lxml, itsdangerous, idna, hyperframe, hpack, h11, grpcio, greenlet, graphemeu, eval-type-backport, et-xmlfile, dnspython, click, charset_normalizer, certifi, cachetools, blinker, bcrypt, annotated-types, aiolimiter, about-time, wtforms, werkzeug, typing-inspection, types-requests, sqlalchemy, rsa, requests, python-docx, python-dateutil, pydantic-core, pyasn1-modules, proto-plus, pandas-stubs, openpyxl, jinja2, httplib2, httpcore, h2, gunicorn, googleapis-common-protos, email-validator, docx, cffi, apscheduler, anyio, alive-progress, requests-toolbelt, pydantic, pandas, httpx, grpcio-status, google-auth, flask, cryptography, sift-stack-py, python-telegram-bot, google-genai, google-auth-httplib2, google-api-core, flask-wtf, flask-sqlalchemy, flask-login, google-api-python-client, google-cloud-speech, google-ai-generativelanguage, google-generativeai
Successfully installed Pillow-11.3.0 PyYAML-6.0.2 about-time-4.2.1 aiolimiter-1.2.1 alive-progress-3.3.0 annotated-types-0.7.0 anyio-4.10.0 apscheduler-3.11.0 bcrypt-4.3.0 blinker-1.9.0 cachetools-5.5.2 certifi-2025.8.3 cffi-2.0.0b1 charset_normalizer-3.4.3 click-8.2.1 cryptography-45.0.7 dnspython-2.7.0 docx-0.2.4 email-validator-2.3.0 et-xmlfile-2.0.0 eval-type-backport-0.2.2 flask-3.1.2 flask-login-0.6.3 flask-sqlalchemy-3.1.1 flask-wtf-1.2.2 google-ai-generativelanguage-0.6.15 google-api-core-2.25.1 google-api-python-client-2.181.0 google-auth-2.40.3 google-auth-httplib2-0.2.0 google-cloud-speech-2.33.0 google-genai-1.33.0 google-generativeai-0.8.5 googleapis-common-protos-1.70.0 graphemeu-0.7.2 greenlet-3.2.4 grpcio-1.74.0 grpcio-status-1.71.2 gunicorn-23.0.0 h11-0.16.0 h2-4.3.0 hpack-4.1.0 httpcore-1.0.9 httplib2-0.30.0 httpx-0.28.1 hyperframe-6.1.0 idna-3.10 itsdangerous-2.2.0 jinja2-3.1.6 lxml-6.0.1 markupsafe-3.0.2 numpy-2.3.2 openpyxl-3.1.5 packaging-25.0 pandas-2.3.2 pandas-stubs-2.3.2.250827 proto-plus-1.26.1 protobuf-5.29.5 psycopg2-binary-2.9.10 pyasn1-0.6.1 pyasn1-modules-0.4.2 pycparser-2.22 pydantic-2.11.7 pydantic-core-2.33.2 pydub-0.25.1 pyparsing-3.2.3 python-dateutil-2.9.0.post0 python-docx-1.2.0 python-telegram-bot-22.3 pytz-2025.2 requests-2.32.5 requests-toolbelt-1.0.0 rsa-4.9.1 schedule-1.2.2 sift-stack-py-0.8.5 six-1.17.0 sniffio-1.3.1 socksio-1.0.0 sqlalchemy-2.0.43 telegram-0.0.1 tenacity-9.1.2 tornado-6.5.2 tqdm-4.67.1 types-PyYAML-6.0.12.20250822 types-protobuf-6.30.2.20250822 types-pytz-2025.2.0.20250809 types-requests-2.32.4.20250809 typing-extensions-4.15.0 typing-inspection-0.4.1 tzdata-2025.2 tzlocal-5.3.1 uritemplate-4.2.0 urllib3-2.5.0 websockets-15.0.1 werkzeug-3.1.3 wtforms-3.2.1
[notice] A new release of pip is available: 25.1.1 -> 25.2
[notice] To update, run: pip install --upgrade pip
==> Uploading build...
==> Uploaded in 6.8s. Compression took 3.0s
==> Build successful ðŸŽ‰
==> Deploying...
==> Running 'gunicorn main:app'
[05:51:16] INFO: BotFactory AI logging system initialized successfully
[05:51:16] INFO: BotFactory AI logging system initialized successfully
[05:51:16] INFO: BotFactory AI application starting with professional logging
==> No open ports detected, continuing to scan...
==> Docs on specifying a port: https://render.com/docs/web-services#port-binding
[05:51:40] ERROR: Database initialization error: (psycopg2.OperationalError) could not translate host name "dpg-d2sq2275r7bs73aocip0-a" to address: Name or service not known
(Background on this error at: https://sqlalche.me/e/20/e3q8)
[2025-09-05 05:51:40 +0000] [56] [INFO] Starting gunicorn 23.0.0
[2025-09-05 05:51:40 +0000] [56] [INFO] Listening at: http://0.0.0.0:10000 (56)
[2025-09-05 05:51:40 +0000] [56] [INFO] Using worker: sync
[2025-09-05 05:51:40 +0000] [64] [INFO] Booting worker with pid: 64
127.0.0.1 - - [05/Sep/2025:05:51:41 +0000] "HEAD / HTTP/1.1" 200 0 "-" "Go-http-client/1.1"
==> Your service is live ðŸŽ‰
==> 
==> ///////////////////////////////////////////////////////////
==> 
==> Available at your primary URL https://chatbotfactory.onrender.com
==> 
==> ///////////////////////////////////////////////////////////
10.204.212.157 - - [05/Sep/2025:05:51:44 +0000] "GET / HTTP/1.1" 200 17938 "-" "Go-http-client/2.0"
[05:51:52] INFO: Registration attempt for username: ass, email: wqsffsak@gmail.com
[05:51:53] ERROR: Registration error for ass: (psycopg2.OperationalError) could not translate host name "dpg-d2sq2275r7bs73aocip0-a" to address: Name or service not known
(Background on this error at: https://sqlalche.me/e/20/e3q8)
Traceback (most recent call last):
  File "/opt/render/project/src/.venv/lib/python3.13/site-packages/sqlalchemy/engine/base.py", line 143, in __init__
    self._dbapi_connection = engine.raw_connection()
                             ~~~~~~~~~~~~~~~~~~~~~^^
  File "/opt/render/project/src/.venv/lib/python3.13/site-packages/sqlalchemy/engine/base.py", line 3301, in raw_connection
    return self.pool.connect()
           ~~~~~~~~~~~~~~~~~^^
  File "/opt/render/project/src/.venv/lib/python3.13/site-packages/sqlalchemy/pool/base.py", line 447, in connect
    return _ConnectionFairy._checkout(self)
           ~~~~~~~~~~~~~~~~~~~~~~~~~~^^^^^^
  File "/opt/render/project/src/.venv/lib/python3.13/site-packages/sqlalchemy/pool/base.py", line 1264, in _checkout
    fairy = _ConnectionRecord.checkout(pool)
  File "/opt/render/project/src/.venv/lib/python3.13/site-packages/sqlalchemy/pool/base.py", line 711, in checkout
    rec = pool._do_get()
  File "/opt/render/project/src/.venv/lib/python3.13/site-packages/sqlalchemy/pool/impl.py", line 177, in _do_get
    with util.safe_reraise():
         ~~~~~~~~~~~~~~~~~^^
  File "/opt/render/project/src/.venv/lib/python3.13/site-packages/sqlalchemy/util/langhelpers.py", line 224, in __exit__
    raise exc_value.with_traceback(exc_tb)
  File "/opt/render/project/src/.venv/lib/python3.13/site-packages/sqlalchemy/pool/impl.py", line 175, in _do_get
    return self._create_connection()
           ~~~~~~~~~~~~~~~~~~~~~~~^^
  File "/opt/render/project/src/.venv/lib/python3.13/site-packages/sqlalchemy/pool/base.py", line 388, in _create_connection
    return _ConnectionRecord(self)
  File "/opt/render/project/src/.venv/lib/python3.13/site-packages/sqlalchemy/pool/base.py", line 673, in __init__
    self.__connect()
    ~~~~~~~~~~~~~~^^
  File "/opt/render/project/src/.venv/lib/python3.13/site-packages/sqlalchemy/pool/base.py", line 899, in __connect
    with util.safe_reraise():
         ~~~~~~~~~~~~~~~~~^^
  File "/opt/render/project/src/.venv/lib/python3.13/site-packages/sqlalchemy/util/langhelpers.py", line 224, in __exit__
    raise exc_value.with_traceback(exc_tb)
  File "/opt/render/project/src/.venv/lib/python3.13/site-packages/sqlalchemy/pool/base.py", line 895, in __connect
    self.dbapi_connection = connection = pool._invoke_creator(self)
                                         ~~~~~~~~~~~~~~~~~~~~^^^^^^
  File "/opt/render/project/src/.venv/lib/python3.13/site-packages/sqlalchemy/engine/create.py", line 661, in connect
    return dialect.connect(*cargs, **cparams)
           ~~~~~~~~~~~~~~~^^^^^^^^^^^^^^^^^^^
  File "/opt/render/project/src/.venv/lib/python3.13/site-packages/sqlalchemy/engine/default.py", line 629, in connect
    return self.loaded_dbapi.connect(*cargs, **cparams)  # type: ignore[no-any-return]  # NOQA: E501
           ~~~~~~~~~~~~~~~~~~~~~~~~~^^^^^^^^^^^^^^^^^^^
  File "/opt/render/project/src/.venv/lib/python3.13/site-packages/psycopg2/__init__.py", line 122, in connect
    conn = _connect(dsn, connection_factory=connection_factory, **kwasync)
psycopg2.OperationalError: could not translate host name "dpg-d2sq2275r7bs73aocip0-a" to address: Name or service not known
The above exception was the direct cause of the following exception:
Traceback (most recent call last):
  File "/opt/render/project/src/auth.py", line 67, in register
    if User.query.filter_by(username=username).first():
       ~~~~~~~~~~~~~~~~~~~~~~~~~~~~~~~~~~~~~~~~~~~~~^^
  File "/opt/render/project/src/.venv/lib/python3.13/site-packages/sqlalchemy/orm/query.py", line 2759, in first
    return self.limit(1)._iter().first()  # type: ignore
           ~~~~~~~~~~~~~~~~~~~^^
  File "/opt/render/project/src/.venv/lib/python3.13/site-packages/sqlalchemy/orm/query.py", line 2857, in _iter
    result: Union[ScalarResult[_T], Result[_T]] = self.session.execute(
                                                  ~~~~~~~~~~~~~~~~~~~~^
        statement,
        ^^^^^^^^^^
        params,
        ^^^^^^^
        execution_options={"_sa_orm_load_options": self.load_options},
        ^^^^^^^^^^^^^^^^^^^^^^^^^^^^^^^^^^^^^^^^^^^^^^^^^^^^^^^^^^^^^^
    )
    ^
  File "/opt/render/project/src/.venv/lib/python3.13/site-packages/sqlalchemy/orm/session.py", line 2365, in execute
    return self._execute_internal(
           ~~~~~~~~~~~~~~~~~~~~~~^
        statement,
        ^^^^^^^^^^
    ...<4 lines>...
        _add_event=_add_event,
        ^^^^^^^^^^^^^^^^^^^^^^
    )
    ^
  File "/opt/render/project/src/.venv/lib/python3.13/site-packages/sqlalchemy/orm/session.py", line 2241, in _execute_internal
    conn = self._connection_for_bind(bind)
  File "/opt/render/project/src/.venv/lib/python3.13/site-packages/sqlalchemy/orm/session.py", line 2110, in _connection_for_bind
    return trans._connection_for_bind(engine, execution_options)
           ~~~~~~~~~~~~~~~~~~~~~~~~~~^^^^^^^^^^^^^^^^^^^^^^^^^^^
  File "<string>", line 2, in _connection_for_bind
  File "/opt/render/project/src/.venv/lib/python3.13/site-packages/sqlalchemy/orm/state_changes.py", line 137, in _go
    ret_value = fn(self, *arg, **kw)
  File "/opt/render/project/src/.venv/lib/python3.13/site-packages/sqlalchemy/orm/session.py", line 1189, in _connection_for_bind
    conn = bind.connect()
  File "/opt/render/project/src/.venv/lib/python3.13/site-packages/sqlalchemy/engine/base.py", line 3277, in connect
    return self._connection_cls(self)
           ~~~~~~~~~~~~~~~~~~~~^^^^^^
  File "/opt/render/project/src/.venv/lib/python3.13/site-packages/sqlalchemy/engine/base.py", line 145, in __init__
    Connection._handle_dbapi_exception_noconnection(
    ~~~~~~~~~~~~~~~~~~~~~~~~~~~~~~~~~~~~~~~~~~~~~~~^
        err, dialect, engine
        ^^^^^^^^^^^^^^^^^^^^
    )
    ^
  File "/opt/render/project/src/.venv/lib/python3.13/site-packages/sqlalchemy/engine/base.py", line 2440, in _handle_dbapi_exception_noconnection
    raise sqlalchemy_exception.with_traceback(exc_info[2]) from e
  File "/opt/render/project/src/.venv/lib/python3.13/site-packages/sqlalchemy/engine/base.py", line 143, in __init__
    self._dbapi_connection = engine.raw_connection()
                             ~~~~~~~~~~~~~~~~~~~~~^^
  File "/opt/render/project/src/.venv/lib/python3.13/site-packages/sqlalchemy/engine/base.py", line 3301, in raw_connection
    return self.pool.connect()
           ~~~~~~~~~~~~~~~~~^^
  File "/opt/render/project/src/.venv/lib/python3.13/site-packages/sqlalchemy/pool/base.py", line 447, in connect
    return _ConnectionFairy._checkout(self)
           ~~~~~~~~~~~~~~~~~~~~~~~~~~^^^^^^
  File "/opt/render/project/src/.venv/lib/python3.13/site-packages/sqlalchemy/pool/base.py", line 1264, in _checkout
    fairy = _ConnectionRecord.checkout(pool)
  File "/opt/render/project/src/.venv/lib/python3.13/site-packages/sqlalchemy/pool/base.py", line 711, in checkout
    rec = pool._do_get()
  File "/opt/render/project/src/.venv/lib/python3.13/site-packages/sqlalchemy/pool/impl.py", line 177, in _do_get
    with util.safe_reraise():
         ~~~~~~~~~~~~~~~~~^^
  File "/opt/render/project/src/.venv/lib/python3.13/site-packages/sqlalchemy/util/langhelpers.py", line 224, in __exit__
    raise exc_value.with_traceback(exc_tb)
  File "/opt/render/project/src/.venv/lib/python3.13/site-packages/sqlalchemy/pool/impl.py", line 175, in _do_get
    return self._create_connection()
           ~~~~~~~~~~~~~~~~~~~~~~~^^
  File "/opt/render/project/src/.venv/lib/python3.13/site-packages/sqlalchemy/pool/base.py", line 388, in _create_connection
    return _ConnectionRecord(self)
  File "/opt/render/project/src/.venv/lib/python3.13/site-packages/sqlalchemy/pool/base.py", line 673, in __init__
    self.__connect()
    ~~~~~~~~~~~~~~^^
  File "/opt/render/project/src/.venv/lib/python3.13/site-packages/sqlalchemy/pool/base.py", line 899, in __connect
    with util.safe_reraise():
         ~~~~~~~~~~~~~~~~~^^
  File "/opt/render/project/src/.venv/lib/python3.13/site-packages/sqlalchemy/util/langhelpers.py", line 224, in __exit__
    raise exc_value.with_traceback(exc_tb)
  File "/opt/render/project/src/.venv/lib/python3.13/site-packages/sqlalchemy/pool/base.py", line 895, in __connect
    self.dbapi_connection = connection = pool._invoke_creator(self)
                                         ~~~~~~~~~~~~~~~~~~~~^^^^^^
  File "/opt/render/project/src/.venv/lib/python3.13/site-packages/sqlalchemy/engine/create.py", line 661, in connect
    return dialect.connect(*cargs, **cparams)
           ~~~~~~~~~~~~~~~^^^^^^^^^^^^^^^^^^^
  File "/opt/render/project/src/.venv/lib/python3.13/site-packages/sqlalchemy/engine/default.py", line 629, in connect
    return self.loaded_dbapi.connect(*cargs, **cparams)  # type: ignore[no-any-return]  # NOQA: E501
           ~~~~~~~~~~~~~~~~~~~~~~~~~^^^^^^^^^^^^^^^^^^^
  File "/opt/render/project/src/.venv/lib/python3.13/site-packages/psycopg2/__init__.py", line 122, in connect
    conn = _connect(dsn, connection_factory=connection_factory, **kwasync)
sqlalchemy.exc.OperationalError: (psycopg2.OperationalError) could not translate host name "dpg-d2sq2275r7bs73aocip0-a" to address: Name or service not known
(Background on this error at: https://sqlalche.me/e/20/e3q8)
10.204.13.64 - - [05/Sep/2025:05:51:53 +0000] "POST /auth/register HTTP/1.1" 200 13140 "https://chatbotfactory.onrender.com/auth/register" "Mozilla/5.0 (Windows NT 10.0; Win64; x64) AppleWebKit/537.36 (KHTML, like Gecko) Chrome/140.0.0.0 Safari/537.36"
[05:52:14] INFO: Registration attempt for username: qervd, email: sffssask@gmail.com
[05:52:14] ERROR: Registration error for qervd: (psycopg2.OperationalError) could not translate host name "dpg-d2sq2275r7bs73aocip0-a" to address: Name or service not known
(Background on this error at: https://sqlalche.me/e/20/e3q8)
Traceback (most recent call last):
  File "/opt/render/project/src/.venv/lib/python3.13/site-packages/sqlalchemy/engine/base.py", line 143, in __init__
    self._dbapi_connection = engine.raw_connection()
                             ~~~~~~~~~~~~~~~~~~~~~^^
  File "/opt/render/project/src/.venv/lib/python3.13/site-packages/sqlalchemy/engine/base.py", line 3301, in raw_connection
    return self.pool.connect()
           ~~~~~~~~~~~~~~~~~^^
  File "/opt/render/project/src/.venv/lib/python3.13/site-packages/sqlalchemy/pool/base.py", line 447, in connect
    return _ConnectionFairy._checkout(self)
           ~~~~~~~~~~~~~~~~~~~~~~~~~~^^^^^^
  File "/opt/render/project/src/.venv/lib/python3.13/site-packages/sqlalchemy/pool/base.py", line 1264, in _checkout
    fairy = _ConnectionRecord.checkout(pool)
  File "/opt/render/project/src/.venv/lib/python3.13/site-packages/sqlalchemy/pool/base.py", line 711, in checkout
    rec = pool._do_get()
  File "/opt/render/project/src/.venv/lib/python3.13/site-packages/sqlalchemy/pool/impl.py", line 177, in _do_get
    with util.safe_reraise():
         ~~~~~~~~~~~~~~~~~^^
  File "/opt/render/project/src/.venv/lib/python3.13/site-packages/sqlalchemy/util/langhelpers.py", line 224, in __exit__
    raise exc_value.with_traceback(exc_tb)
  File "/opt/render/project/src/.venv/lib/python3.13/site-packages/sqlalchemy/pool/impl.py", line 175, in _do_get
    return self._create_connection()
           ~~~~~~~~~~~~~~~~~~~~~~~^^
  File "/opt/render/project/src/.venv/lib/python3.13/site-packages/sqlalchemy/pool/base.py", line 388, in _create_connection
    return _ConnectionRecord(self)
  File "/opt/render/project/src/.venv/lib/python3.13/site-packages/sqlalchemy/pool/base.py", line 673, in __init__
    self.__connect()
    ~~~~~~~~~~~~~~^^
  File "/opt/render/project/src/.venv/lib/python3.13/site-packages/sqlalchemy/pool/base.py", line 899, in __connect
    with util.safe_reraise():
         ~~~~~~~~~~~~~~~~~^^
  File "/opt/render/project/src/.venv/lib/python3.13/site-packages/sqlalchemy/util/langhelpers.py", line 224, in __exit__
    raise exc_value.with_traceback(exc_tb)
  File "/opt/render/project/src/.venv/lib/python3.13/site-packages/sqlalchemy/pool/base.py", line 895, in __connect
    self.dbapi_connection = connection = pool._invoke_creator(self)
                                         ~~~~~~~~~~~~~~~~~~~~^^^^^^
  File "/opt/render/project/src/.venv/lib/python3.13/site-packages/sqlalchemy/engine/create.py", line 661, in connect
    return dialect.connect(*cargs, **cparams)
           ~~~~~~~~~~~~~~~^^^^^^^^^^^^^^^^^^^
  File "/opt/render/project/src/.venv/lib/python3.13/site-packages/sqlalchemy/engine/default.py", line 629, in connect
    return self.loaded_dbapi.connect(*cargs, **cparams)  # type: ignore[no-any-return]  # NOQA: E501
           ~~~~~~~~~~~~~~~~~~~~~~~~~^^^^^^^^^^^^^^^^^^^
  File "/opt/render/project/src/.venv/lib/python3.13/site-packages/psycopg2/__init__.py", line 122, in connect
    conn = _connect(dsn, connection_factory=connection_factory, **kwasync)
psycopg2.OperationalError: could not translate host name "dpg-d2sq2275r7bs73aocip0-a" to address: Name or service not known
The above exception was the direct cause of the following exception:
Traceback (most recent call last):
  File "/opt/render/project/src/auth.py", line 67, in register
    if User.query.filter_by(username=username).first():
       ~~~~~~~~~~~~~~~~~~~~~~~~~~~~~~~~~~~~~~~~~~~~~^^
  File "/opt/render/project/src/.venv/lib/python3.13/site-packages/sqlalchemy/orm/query.py", line 2759, in first
    return self.limit(1)._iter().first()  # type: ignore
           ~~~~~~~~~~~~~~~~~~~^^
  File "/opt/render/project/src/.venv/lib/python3.13/site-packages/sqlalchemy/orm/query.py", line 2857, in _iter
    result: Union[ScalarResult[_T], Result[_T]] = self.session.execute(
                                                  ~~~~~~~~~~~~~~~~~~~~^
        statement,
        ^^^^^^^^^^
        params,
        ^^^^^^^
        execution_options={"_sa_orm_load_options": self.load_options},
        ^^^^^^^^^^^^^^^^^^^^^^^^^^^^^^^^^^^^^^^^^^^^^^^^^^^^^^^^^^^^^^
    )
    ^
  File "/opt/render/project/src/.venv/lib/python3.13/site-packages/sqlalchemy/orm/session.py", line 2365, in execute
    return self._execute_internal(
           ~~~~~~~~~~~~~~~~~~~~~~^
        statement,
        ^^^^^^^^^^
    ...<4 lines>...
        _add_event=_add_event,
        ^^^^^^^^^^^^^^^^^^^^^^
    )
    ^
  File "/opt/render/project/src/.venv/lib/python3.13/site-packages/sqlalchemy/orm/session.py", line 2241, in _execute_internal
    conn = self._connection_for_bind(bind)
  File "/opt/render/project/src/.venv/lib/python3.13/site-packages/sqlalchemy/orm/session.py", line 2110, in _connection_for_bind
    return trans._connection_for_bind(engine, execution_options)
           ~~~~~~~~~~~~~~~~~~~~~~~~~~^^^^^^^^^^^^^^^^^^^^^^^^^^^
  File "<string>", line 2, in _connection_for_bind
  File "/opt/render/project/src/.venv/lib/python3.13/site-packages/sqlalchemy/orm/state_changes.py", line 137, in _go
    ret_value = fn(self, *arg, **kw)
  File "/opt/render/project/src/.venv/lib/python3.13/site-packages/sqlalchemy/orm/session.py", line 1189, in _connection_for_bind
    conn = bind.connect()
  File "/opt/render/project/src/.venv/lib/python3.13/site-packages/sqlalchemy/engine/base.py", line 3277, in connect
    return self._connection_cls(self)
           ~~~~~~~~~~~~~~~~~~~~^^^^^^
  File "/opt/render/project/src/.venv/lib/python3.13/site-packages/sqlalchemy/engine/base.py", line 145, in __init__
    Connection._handle_dbapi_exception_noconnection(
    ~~~~~~~~~~~~~~~~~~~~~~~~~~~~~~~~~~~~~~~~~~~~~~~^
        err, dialect, engine
        ^^^^^^^^^^^^^^^^^^^^
    )
    ^
  File "/opt/render/project/src/.venv/lib/python3.13/site-packages/sqlalchemy/engine/base.py", line 2440, in _handle_dbapi_exception_noconnection
    raise sqlalchemy_exception.with_traceback(exc_info[2]) from e
  File "/opt/render/project/src/.venv/lib/python3.13/site-packages/sqlalchemy/engine/base.py", line 143, in __init__
    self._dbapi_connection = engine.raw_connection()
                             ~~~~~~~~~~~~~~~~~~~~~^^
  File "/opt/render/project/src/.venv/lib/python3.13/site-packages/sqlalchemy/engine/base.py", line 3301, in raw_connection
    return self.pool.connect()
           ~~~~~~~~~~~~~~~~~^^
  File "/opt/render/project/src/.venv/lib/python3.13/site-packages/sqlalchemy/pool/base.py", line 447, in connect
    return _ConnectionFairy._checkout(self)
           ~~~~~~~~~~~~~~~~~~~~~~~~~~^^^^^^
  File "/opt/render/project/src/.venv/lib/python3.13/site-packages/sqlalchemy/pool/base.py", line 1264, in _checkout
    fairy = _ConnectionRecord.checkout(pool)
  File "/opt/render/project/src/.venv/lib/python3.13/site-packages/sqlalchemy/pool/base.py", line 711, in checkout
    rec = pool._do_get()
  File "/opt/render/project/src/.venv/lib/python3.13/site-packages/sqlalchemy/pool/impl.py", line 177, in _do_get
    with util.safe_reraise():
         ~~~~~~~~~~~~~~~~~^^
  File "/opt/render/project/src/.venv/lib/python3.13/site-packages/sqlalchemy/util/langhelpers.py", line 224, in __exit__
    raise exc_value.with_traceback(exc_tb)
  File "/opt/render/project/src/.venv/lib/python3.13/site-packages/sqlalchemy/pool/impl.py", line 175, in _do_get
    return self._create_connection()
           ~~~~~~~~~~~~~~~~~~~~~~~^^
  File "/opt/render/project/src/.venv/lib/python3.13/site-packages/sqlalchemy/pool/base.py", line 388, in _create_connection
    return _ConnectionRecord(self)
  File "/opt/render/project/src/.venv/lib/python3.13/site-packages/sqlalchemy/pool/base.py", line 673, in __init__
    self.__connect()
    ~~~~~~~~~~~~~~^^
  File "/opt/render/project/src/.venv/lib/python3.13/site-packages/sqlalchemy/pool/base.py", line 899, in __connect
    with util.safe_reraise():
         ~~~~~~~~~~~~~~~~~^^
  File "/opt/render/project/src/.venv/lib/python3.13/site-packages/sqlalchemy/util/langhelpers.py", line 224, in __exit__
    raise exc_value.with_traceback(exc_tb)
  File "/opt/render/project/src/.venv/lib/python3.13/site-packages/sqlalchemy/pool/base.py", line 895, in __connect
    self.dbapi_connection = connection = pool._invoke_creator(self)
                                         ~~~~~~~~~~~~~~~~~~~~^^^^^^
  File "/opt/render/project/src/.venv/lib/python3.13/site-packages/sqlalchemy/engine/create.py", line 661, in connect
    return dialect.connect(*cargs, **cparams)
           ~~~~~~~~~~~~~~~^^^^^^^^^^^^^^^^^^^
  File "/opt/render/project/src/.venv/lib/python3.13/site-packages/sqlalchemy/engine/default.py", line 629, in connect
    return self.loaded_dbapi.connect(*cargs, **cparams)  # type: ignore[no-any-return]  # NOQA: E501
           ~~~~~~~~~~~~~~~~~~~~~~~~~^^^^^^^^^^^^^^^^^^^
  File "/opt/render/project/src/.venv/lib/python3.13/site-packages/psycopg2/__init__.py", line 122, in connect
    conn = _connect(dsn, connection_factory=connection_factory, **kwasync)
sqlalchemy.exc.OperationalError: (psycopg2.OperationalError) could not translate host name "dpg-d2sq2275r7bs73aocip0-a" to address: Name or service not known
(Background on this error at: https://sqlalche.me/e/20/e3q8)
10.204.234.249 - - [05/Sep/2025:05:52:14 +0000] "POST /auth/register HTTP/1.1" 200 13140 "https://chatbotfactory.onrender.com/auth/register" "Mozilla/5.0 (Windows NT 10.0; Win64; x64) AppleWebKit/537.36 (KHTML, like Gecko) Chrome/140.0.0.0 Safari/537.36"
10.204.212.157 - - [05/Sep/2025:05:52:21 +0000] "GET /auth/login HTTP/1.1" 200 9828 "https://chatbotfactory.onrender.com/auth/register" "Mozilla/5.0 (Windows NT 10.0; Win64; x64) AppleWebKit/537.36 (KHTML, like Gecko) Chrome/140.0.0.0 Safari/537.36"
[05:52:23] ERROR: Exception on /auth/login [POST]
Traceback (most recent call last):
  File "/opt/render/project/src/.venv/lib/python3.13/site-packages/sqlalchemy/engine/base.py", line 143, in __init__
    self._dbapi_connection = engine.raw_connection()
                             ~~~~~~~~~~~~~~~~~~~~~^^
  File "/opt/render/project/src/.venv/lib/python3.13/site-packages/sqlalchemy/engine/base.py", line 3301, in raw_connection
    return self.pool.connect()
           ~~~~~~~~~~~~~~~~~^^
  File "/opt/render/project/src/.venv/lib/python3.13/site-packages/sqlalchemy/pool/base.py", line 447, in connect
    return _ConnectionFairy._checkout(self)
           ~~~~~~~~~~~~~~~~~~~~~~~~~~^^^^^^
  File "/opt/render/project/src/.venv/lib/python3.13/site-packages/sqlalchemy/pool/base.py", line 1264, in _checkout
    fairy = _ConnectionRecord.checkout(pool)
  File "/opt/render/project/src/.venv/lib/python3.13/site-packages/sqlalchemy/pool/base.py", line 711, in checkout
    rec = pool._do_get()
  File "/opt/render/project/src/.venv/lib/python3.13/site-packages/sqlalchemy/pool/impl.py", line 177, in _do_get
    with util.safe_reraise():
         ~~~~~~~~~~~~~~~~~^^
  File "/opt/render/project/src/.venv/lib/python3.13/site-packages/sqlalchemy/util/langhelpers.py", line 224, in __exit__
    raise exc_value.with_traceback(exc_tb)
  File "/opt/render/project/src/.venv/lib/python3.13/site-packages/sqlalchemy/pool/impl.py", line 175, in _do_get
    return self._create_connection()
           ~~~~~~~~~~~~~~~~~~~~~~~^^
  File "/opt/render/project/src/.venv/lib/python3.13/site-packages/sqlalchemy/pool/base.py", line 388, in _create_connection
    return _ConnectionRecord(self)
  File "/opt/render/project/src/.venv/lib/python3.13/site-packages/sqlalchemy/pool/base.py", line 673, in __init__
    self.__connect()
    ~~~~~~~~~~~~~~^^
  File "/opt/render/project/src/.venv/lib/python3.13/site-packages/sqlalchemy/pool/base.py", line 899, in __connect
    with util.safe_reraise():
         ~~~~~~~~~~~~~~~~~^^
  File "/opt/render/project/src/.venv/lib/python3.13/site-packages/sqlalchemy/util/langhelpers.py", line 224, in __exit__
    raise exc_value.with_traceback(exc_tb)
  File "/opt/render/project/src/.venv/lib/python3.13/site-packages/sqlalchemy/pool/base.py", line 895, in __connect
    self.dbapi_connection = connection = pool._invoke_creator(self)
                                         ~~~~~~~~~~~~~~~~~~~~^^^^^^
  File "/opt/render/project/src/.venv/lib/python3.13/site-packages/sqlalchemy/engine/create.py", line 661, in connect
    return dialect.connect(*cargs, **cparams)
           ~~~~~~~~~~~~~~~^^^^^^^^^^^^^^^^^^^
  File "/opt/render/project/src/.venv/lib/python3.13/site-packages/sqlalchemy/engine/default.py", line 629, in connect
    return self.loaded_dbapi.connect(*cargs, **cparams)  # type: ignore[no-any-return]  # NOQA: E501
           ~~~~~~~~~~~~~~~~~~~~~~~~~^^^^^^^^^^^^^^^^^^^
  File "/opt/render/project/src/.venv/lib/python3.13/site-packages/psycopg2/__init__.py", line 122, in connect
    conn = _connect(dsn, connection_factory=connection_factory, **kwasync)
psycopg2.OperationalError: could not translate host name "dpg-d2sq2275r7bs73aocip0-a" to address: Name or service not known
The above exception was the direct cause of the following exception:
Traceback (most recent call last):
  File "/opt/render/project/src/.venv/lib/python3.13/site-packages/flask/app.py", line 1511, in wsgi_app
    response = self.full_dispatch_request()
  File "/opt/render/project/src/.venv/lib/python3.13/site-packages/flask/app.py", line 919, in full_dispatch_request
    rv = self.handle_user_exception(e)
  File "/opt/render/project/src/.venv/lib/python3.13/site-packages/flask/app.py", line 917, in full_dispatch_request
    rv = self.dispatch_request()
  File "/opt/render/project/src/.venv/lib/python3.13/site-packages/flask/app.py", line 902, in dispatch_request
    return self.ensure_sync(self.view_functions[rule.endpoint])(**view_args)  # type: ignore[no-any-return]
           ~~~~~~~~~~~~~~~~~~~~~~~~~~~~~~~~~~~~~~~~~~~~~~~~~~~~^^^^^^^^^^^^^
  File "/opt/render/project/src/auth.py", line 24, in login
    user = User.query.filter_by(username=username).first()
  File "/opt/render/project/src/.venv/lib/python3.13/site-packages/sqlalchemy/orm/query.py", line 2759, in first
    return self.limit(1)._iter().first()  # type: ignore
           ~~~~~~~~~~~~~~~~~~~^^
  File "/opt/render/project/src/.venv/lib/python3.13/site-packages/sqlalchemy/orm/query.py", line 2857, in _iter
    result: Union[ScalarResult[_T], Result[_T]] = self.session.execute(
                                                  ~~~~~~~~~~~~~~~~~~~~^
        statement,
        ^^^^^^^^^^
        params,
        ^^^^^^^
        execution_options={"_sa_orm_load_options": self.load_options},
        ^^^^^^^^^^^^^^^^^^^^^^^^^^^^^^^^^^^^^^^^^^^^^^^^^^^^^^^^^^^^^^
    )
    ^
  File "/opt/render/project/src/.venv/lib/python3.13/site-packages/sqlalchemy/orm/session.py", line 2365, in execute
    return self._execute_internal(
           ~~~~~~~~~~~~~~~~~~~~~~^
        statement,
        ^^^^^^^^^^
    ...<4 lines>...
        _add_event=_add_event,
        ^^^^^^^^^^^^^^^^^^^^^^
    )
    ^
  File "/opt/render/project/src/.venv/lib/python3.13/site-packages/sqlalchemy/orm/session.py", line 2241, in _execute_internal
    conn = self._connection_for_bind(bind)
  File "/opt/render/project/src/.venv/lib/python3.13/site-packages/sqlalchemy/orm/session.py", line 2110, in _connection_for_bind
    return trans._connection_for_bind(engine, execution_options)
           ~~~~~~~~~~~~~~~~~~~~~~~~~~^^^^^^^^^^^^^^^^^^^^^^^^^^^
  File "<string>", line 2, in _connection_for_bind
  File "/opt/render/project/src/.venv/lib/python3.13/site-packages/sqlalchemy/orm/state_changes.py", line 137, in _go
    ret_value = fn(self, *arg, **kw)
  File "/opt/render/project/src/.venv/lib/python3.13/site-packages/sqlalchemy/orm/session.py", line 1189, in _connection_for_bind
    conn = bind.connect()
  File "/opt/render/project/src/.venv/lib/python3.13/site-packages/sqlalchemy/engine/base.py", line 3277, in connect
    return self._connection_cls(self)
           ~~~~~~~~~~~~~~~~~~~~^^^^^^
  File "/opt/render/project/src/.venv/lib/python3.13/site-packages/sqlalchemy/engine/base.py", line 145, in __init__
    Connection._handle_dbapi_exception_noconnection(
    ~~~~~~~~~~~~~~~~~~~~~~~~~~~~~~~~~~~~~~~~~~~~~~~^
        err, dialect, engine
        ^^^^^^^^^^^^^^^^^^^^
    )
    ^
  File "/opt/render/project/src/.venv/lib/python3.13/site-packages/sqlalchemy/engine/base.py", line 2440, in _handle_dbapi_exception_noconnection
    raise sqlalchemy_exception.with_traceback(exc_info[2]) from e
  File "/opt/render/project/src/.venv/lib/python3.13/site-packages/sqlalchemy/engine/base.py", line 143, in __init__
    self._dbapi_connection = engine.raw_connection()
                             ~~~~~~~~~~~~~~~~~~~~~^^
  File "/opt/render/project/src/.venv/lib/python3.13/site-packages/sqlalchemy/engine/base.py", line 3301, in raw_connection
    return self.pool.connect()
           ~~~~~~~~~~~~~~~~~^^
  File "/opt/render/project/src/.venv/lib/python3.13/site-packages/sqlalchemy/pool/base.py", line 447, in connect
    return _ConnectionFairy._checkout(self)
           ~~~~~~~~~~~~~~~~~~~~~~~~~~^^^^^^
  File "/opt/render/project/src/.venv/lib/python3.13/site-packages/sqlalchemy/pool/base.py", line 1264, in _checkout
    fairy = _ConnectionRecord.checkout(pool)
  File "/opt/render/project/src/.venv/lib/python3.13/site-packages/sqlalchemy/pool/base.py", line 711, in checkout
    rec = pool._do_get()
  File "/opt/render/project/src/.venv/lib/python3.13/site-packages/sqlalchemy/pool/impl.py", line 177, in _do_get
    with util.safe_reraise():
         ~~~~~~~~~~~~~~~~~^^
  File "/opt/render/project/src/.venv/lib/python3.13/site-packages/sqlalchemy/util/langhelpers.py", line 224, in __exit__
    raise exc_value.with_traceback(exc_tb)
  File "/opt/render/project/src/.venv/lib/python3.13/site-packages/sqlalchemy/pool/impl.py", line 175, in _do_get
    return self._create_connection()
           ~~~~~~~~~~~~~~~~~~~~~~~^^
  File "/opt/render/project/src/.venv/lib/python3.13/site-packages/sqlalchemy/pool/base.py", line 388, in _create_connection
    return _ConnectionRecord(self)
  File "/opt/render/project/src/.venv/lib/python3.13/site-packages/sqlalchemy/pool/base.py", line 673, in __init__
    self.__connect()
    ~~~~~~~~~~~~~~^^
  File "/opt/render/project/src/.venv/lib/python3.13/site-packages/sqlalchemy/pool/base.py", line 899, in __connect
    with util.safe_reraise():
         ~~~~~~~~~~~~~~~~~^^
  File "/opt/render/project/src/.venv/lib/python3.13/site-packages/sqlalchemy/util/langhelpers.py", line 224, in __exit__
    raise exc_value.with_traceback(exc_tb)
  File "/opt/render/project/src/.venv/lib/python3.13/site-packages/sqlalchemy/pool/base.py", line 895, in __connect
    self.dbapi_connection = connection = pool._invoke_creator(self)
                                         ~~~~~~~~~~~~~~~~~~~~^^^^^^
  File "/opt/render/project/src/.venv/lib/python3.13/site-packages/sqlalchemy/engine/create.py", line 661, in connect
    return dialect.connect(*cargs, **cparams)
           ~~~~~~~~~~~~~~~^^^^^^^^^^^^^^^^^^^
  File "/opt/render/project/src/.venv/lib/python3.13/site-packages/sqlalchemy/engine/default.py", line 629, in connect
    return self.loaded_dbapi.connect(*cargs, **cparams)  # type: ignore[no-any-return]  # NOQA: E501
           ~~~~~~~~~~~~~~~~~~~~~~~~~^^^^^^^^^^^^^^^^^^^
  File "/opt/render/project/src/.venv/lib/python3.13/site-packages/psycopg2/__init__.py", line 122, in connect
    conn = _connect(dsn, connection_factory=connection_factory, **kwasync)
sqlalchemy.exc.OperationalError: (psycopg2.OperationalError) could not translate host name "dpg-d2sq2275r7bs73aocip0-a" to address: Name or service not known
(Background on this error at: https://sqlalche.me/e/20/e3q8)
10.204.13.64 - - [05/Sep/2025:05:52:23 +0000] "POST /auth/login HTTP/1.1" 500 265 "https://chatbotfactory.onrender.com/auth/login" "Mozilla/5.0 (Windows NT 10.0; Win64; x64) AppleWebKit/537.36 (KHTML, like Gecko) Chrome/140.0.0.0 Safari/537.36"